<?xml version="1.0"?>
<robot xmlns:xacro="http://www.ros.org/wiki/xacro">
  <material name="centauri_table">
      <color rgba="1 1 1 1"/>
  </material>

  <material name="centauri_black">
      <color rgba="0.2 0.196078431 0.192156863 1"/>
  </material>

  <material name="centauri_yellow">
      <color rgba="1 1 0 1"/>
  </material>

  <link name="world" />

  <link name="base_link" />

  <joint name="joint_world" type="fixed">
    <parent link="world"/>
    <child link="base_link"/>
    <origin xyz="0.0 0.0 0.125" />
    <axis xyz= "0 0 0" />
  </joint>
  
  <link name="base_footprint">
    <inertial>
      <origin xyz="-3.87008276523659E-05 -0.0817645704237657 -0.030378156140952" rpy="0 0 0" />
      <mass value="3.65383133115989" />
      <inertia  ixx="0.09620416476260482" ixy="0" ixz="0" iyy="0.09620416476260482" iyz="0" izz="0.18421400426477288" />
    </inertial>
    <visual>
      <origin xyz="0 0 0" rpy="0 0 0" />
      <geometry>
        <mesh filename="package://centauri/meshes/base_footprint.STL" />
      </geometry>
      <material name="centauri_table"/>
    </visual>
    <collision>
      <origin
        xyz="0 0 0"
        rpy="0 0 0" />
      <geometry>
        <mesh filename="package://centauri/meshes/base_footprint.STL" />
      </geometry>
    </collision>
  </link>

  <joint name="joint_base" type="fixed">
    <origin xyz="0 0 0" rpy="0 0 0" />
    <parent link="base_link" />
    <child link="base_footprint"  />
    <axis xyz="0 0 0" />
  </joint>

<!--//////////////////////////////////////////////////////////-->
  <link name="link0">
    <inertial>
      <origin xyz="0.0807291362657826 1.35637930692711E-07 0.0322703892739422" rpy="0 0 0" />
      <mass value="1.5913265865128" />
      <inertia  ixx="0.006326695700280836" ixy="0" ixz="0" iyy="0.011276109304923142" iyz="0" izz="0.015558257830895829" />
    </inertial>
    <visual>
      <origin xyz="0 0 0" rpy="0 0 0" />
      <geometry>
        <mesh filename="package://centauri/meshes/link0.STL" />
      </geometry>
      <material name="centauri_yellow"/>
    </visual>
    <collision>
      <origin xyz="0 0 0" rpy="0 0 0" />
      <geometry>
        <mesh filename="package://centauri/meshes/link0.STL" />
      </geometry>
    </collision>
  </link>

  <joint name="joint0" type="fixed">
    <origin xyz="0 0 0" rpy="0 0 0" />
    <parent link="base_footprint" />
    <child link="link0" />
    <axis xyz="0 0 0" />
  </joint>

<!--//////////////////////////////////////////////////////////-->
  <link name="link1">
    <inertial>
      <origin xyz="3.76244275456517E-05 0.07417823767633 -8.98233600953868E-05" rpy="0 0 0" />
      <mass value="2.01538850239224" />
      <inertia  ixx="0.013476289068307574" ixy="0" ixz="0" iyy="0.02265511278216395" iyz="0" izz="0.023363884685992" />
    </inertial>
    <visual>
      <origin xyz="0 0 0" rpy="0 0 0" />
      <geometry>
        <mesh filename="package://centauri/meshes/link1.STL" />
      </geometry>
      <material name="centauri_black"/>
    </visual>
    <collision>
      <origin xyz="0 0 0" rpy="0 0 0" />
      <geometry>
        <mesh filename="package://centauri/meshes/link1.STL" />
      </geometry>
    </collision>
  </link>

  <joint name="joint1" type="revolute">
    <origin xyz="0 0 0.0660000000000001" rpy="1.5708963267949 0 -0.452226747641724" />
    <parent link="link0" />
    <child link="link1" />
    <axis xyz="0 1 0" />
    <limit lower="-1.5708" upper="1.5708" effort="300" velocity="1" />
    <dynamics friction="1.5" damping="0.1" />
  </joint>

<!--//////////////////////////////////////////////////////////-->
  <link name="link2">
    <inertial>
      <origin xyz="0.00019803 0.082039 0.0010087" rpy="0 0 0" />
      <mass value="1.9635" />
      <inertia  ixx="0.02063287702209914" ixy="0" ixz="0" iyy="0.0053203652540438325" iyz="0" izz="0.020024715527956653" />
    </inertial>
    <visual>
      <origin xyz="0 0 0" rpy="0 0 0" />
      <geometry>
        <mesh filename="package://centauri/meshes/link2.STL" />
      </geometry>
      <material name="centauri_yellow"/>
    </visual>
    <collision>
      <origin xyz="0 0 0" rpy="0 0 0" />
      <geometry>
        <mesh filename="package://centauri/meshes/link2.STL" />
      </geometry>
    </collision>
  </link>

  <joint name="joint2" type="revolute">
    <origin xyz="0 0.1455 0" rpy="0 -1.11019042810366 0" />
    <parent link="link1" />
    <child link="link2" />
    <axis xyz="0 0 -1" />
    <limit lower="-1.5708" upper="1.5708" effort="5" velocity="1" />
    <dynamics friction="1.5" damping="0.1" />
  </joint>

<!--//////////////////////////////////////////////////////////-->

  <link name="link3">
    <inertial>
      <origin xyz="0.000626139076089688 0.0486487096653359 0.000675674262400602" rpy="0 0 0" />
      <mass value="1.18050061400462" />
      <inertia  ixx="0.0036077228403450846" ixy="0" ixz="0" iyy="0.0014786512340732411" iyz="0" izz="0.0039046437540969266" />
    </inertial>
    <visual>
      <origin xyz="0 0 0" rpy="0 0 0" />
      <geometry>
        <mesh filename="package://centauri/meshes/link3.STL" />
      </geometry>
      <material name="centauri_black"/>
    </visual>
    <collision>
      <origin xyz="0 0 0" rpy="0 0 0" />
      <geometry>
        <mesh filename="package://centauri/meshes/link3.STL" />
      </geometry>
    </collision>
  </link>

  <joint name="joint3" type="revolute">
    <origin xyz="0.000683655378621667 0.221122735963581 -0.0034958933328718" rpy="-3.51525449374113E-16 3.46944695195361E-18 0" />
    <parent link="link2" />
    <child link="link3" />
    <axis xyz="0 0 -1" />
    <limit lower="-1.5708" upper="1.5708" effort="5" velocity="1" />
    <dynamics friction="1.5" damping="0.1" />
  </joint>

<!--//////////////////////////////////////////////////////////-->
  <link name="link4">
    <inertial>
      <origin xyz="0.011293 -0.00022493 0.045445" rpy="0 0 0" />
      <mass value="0.65268" />
      <inertia  ixx="0.0012004874438368324" ixy="0" ixz="0" iyy="0.001359027438412866" iyz="0" izz="0.0007240865915798544" />
    </inertial>
    <visual>
      <origin xyz="0 0 0" rpy="0 0 0" />
      <geometry>
        <mesh filename="package://centauri/meshes/link4.STL" />
      </geometry>
      <material name="centauri_black"/>
    </visual>
    <collision>
      <origin xyz="0 0 0" rpy="0 0 0" />
      <geometry>
        <mesh filename="package://centauri/meshes/link4.STL" />
      </geometry>
    </collision>
  </link>

  <joint name="joint4" type="revolute">
    <origin xyz="0.00043975 0.1275 0" rpy="-1.5708 1.5624 -0.0034491" />
    <parent link="link3" />
    <child link="link4" />
    <axis xyz="0 0 1" />
    <limit lower="-1.5708" upper="1.5708" effort="5" velocity="1" />
    <dynamics friction="1.5" damping="0.1" />
  </joint>

<!--//////////////////////////////////////////////////////////-->
  <link name="link5">
    <inertial>
      <origin xyz="0.00013449 0.004274 -0.00031217" rpy="0 0 0" />
      <mass value="0.16415" />
      <inertia  ixx="0.0001281536352001132" ixy="0" ixz="0" iyy="9.850019324706154e-05" iyz="0" izz="0.00016362022735135528" />
    </inertial>
    <visual>
      <origin xyz="0 0 0" rpy="0 0 0" />
      <geometry>
        <mesh filename="package://centauri/meshes/link5.STL" />
      </geometry>
      <material name="centauri_yellow"/>
    </visual>
    <collision>
      <origin xyz="0 0 0" rpy="0 0 0" />
      <geometry>
        <mesh filename="package://centauri/meshes/link5.STL" />
      </geometry>
    </collision>
  </link>

  <joint name="joint5" type="revolute">
    <origin xyz="-0.000999998579141709 0 0.0950000000001046" rpy="1.5708963267949 -0.0171419017753631 -1.56911057527423" />
    <parent link="link4" />
    <child link="link5" />
    <axis xyz="0 0 -1" />
    <limit lower="-1.5708" upper="1.5708" effort="5" velocity="1" />
    <dynamics friction="1.5" damping="0.1" />
  </joint>
  
<!--//////////////////////////////////////////////////////////-->
  <link name="link6">
    <inertial>
      <origin xyz="-0.0028307 -0.014417 0.020832" rpy="0 0 0" />
      <mass value="0.064418" />
      <inertia  ixx="4.2630681336324575E-05" ixy="0" ixz="0" iyy="3.4930583457061154E-05" iyz="0" izz="5.1781565956504675E-05" />
    </inertial>
    <visual>
      <origin xyz="0 0 0" rpy="0 0 0" />
      <geometry>
        <mesh filename="package://centauri/meshes/link6.STL" />
      </geometry>
      <material name="centauri_black"/>
    </visual>
    <collision>
      <origin xyz="0 0 0" rpy="0 0 0" />
      <geometry>
        <mesh filename="package://centauri/meshes/link6.STL" />
      </geometry>
    </collision>
  </link>

  <joint name="joint6" type="revolute">
    <origin xyz="0.0012895 0.04098 0" rpy="1.6915E-08 1.5708 1.5393" />
    <parent link="link5" />
    <child link="link6" />
    <axis xyz="5.3025E-05 0 1" />
    <limit lower="-1.5708" upper="1.5708" effort="5" velocity="1" />
    <dynamics friction="1.5" damping="0.1" />
  </joint>

<!--//////////////////////////////////////////////////////////-->
  <link name="gear1">
    <inertial>
      <origin xyz="-0.0065946 -0.00039537 -0.003" rpy="0 0 0" />
      <mass value="0.0048785" />
      <inertia  ixx="3.797704749390775E-07" ixy="0" ixz="0" iyy="1.4245008015482123E-06" iyz="0" izz="1.7750002759784226E-06" />
    </inertial>
    <visual>
      <origin xyz="0 0 0" rpy="0 0 0" />
      <geometry>
        <mesh filename="package://centauri/meshes/gear1.STL" />
      </geometry>
      <material name="centauri_yellow"/>
    </visual>
    <collision>
      <origin xyz="0 0 0" rpy="0 0 0" />
      <geometry>
        <mesh filename="package://centauri/meshes/gear1.STL" />
      </geometry>
    </collision>
  </link>

  <joint name="joint_gear1" type="revolute">
    <origin xyz="-0.0141687811604771 -0.00205172513025526 0.0240007513303376" rpy="1.57089248092531 0.383949555179722 -0.0673010584807898" />
    <parent link="link6" />
    <child link="gear1" />
    <axis xyz="0 0 1" />
    <limit lower="-0.95" upper="0" effort="5" velocity="1" />
    <dynamics friction="1.5" />
  </joint>
  
<!--//////////////////////////////////////////////////////////-->
  <link name="pinza1">
    <inertial>
      <origin xyz="-0.00410677673607357 0.0288723262754511 -0.00325238297571179" rpy="0 0 0" />
      <mass value="0.0104910711600225" />
      <inertia  ixx="4.784038229064912e-06" ixy="0" ixz="0" iyy="7.523532394095715e-07" iyz="0" izz="4.96987367460796e-06" />
    </inertial>
    <visual>
      <origin xyz="0 0 0" rpy="0 0 0" />
      <geometry>
        <mesh filename="package://centauri/meshes/pinza1.STL" />
      </geometry>
      <material name="centauri_yellow"/>
    </visual>
    <collision>
      <origin
        xyz="0 0 0"
        rpy="0 0 0" />
      <geometry>
        <mesh filename="package://centauri/meshes/pinza1.STL" />
      </geometry>
    </collision>
  </link>

  <joint name="joint_pinza1" type="continuous">
    <origin xyz="-0.0399999999999999 0 0" rpy="1.9909768278481E-13 -6.93889390390723E-18 1.08550321509249E-15" />
    <parent link="gear1" />
    <child link="pinza1" />
    <axis xyz="0 0 1" />
    <limit lower="-1.5" upper="0" effort="5" velocity="1" />
    <mimic joint="joint_gear1" multiplier="-1" offset="0"/>
    <dynamics friction="1.5"/>
  </joint>

<!--//////////////////////////////////////////////////////////-->
  <link name="gear2">
    <inertial>
      <origin xyz="-0.00645273828292098 0.000406646504403807 -0.00300000575998524" rpy="0 0 0" />
      <mass value="0.00500318588067354" />
      <inertia  ixx="3.893573546761533e-07" ixy="0" ixz="0" iyy="1.4663493133889125e-06" iyz="0" izz="1.8256875522591515e-06" />
    </inertial>
    <visual>
      <origin xyz="0 0 0" rpy="0 0 0" />
      <geometry>
        <mesh filename="package://centauri/meshes/gear2.STL" />
      </geometry>
      <material name="centauri_yellow"/>
    </visual>
    <collision>
      <origin xyz="0 0 0" rpy="0 0 0" />
      <geometry>
        <mesh filename="package://centauri/meshes/gear2.STL" />
      </geometry>
    </collision>
  </link>

  <joint name="joint_gear2" type="revolute">
    <origin xyz="0.0137678333896608 -0.00393469228070031 0.0239992699974896" rpy="-1.57089245405947 0.400771502354884 3.07429454658117" />
    <parent link="link6" />
    <child link="gear2" />
    <axis xyz="0 0 1" />
    <limit lower="0" upper="0.95" effort="5" velocity="1" />
    <!--<mimic joint="joint_gear1" multiplier="-1" offset="0"/>-->
    <dynamics friction="1.5" />
  </joint>

<!--//////////////////////////////////////////////////////////-->
  <link name="pinza2">
    <inertial>
      <origin xyz="-0.00459491181291338 -0.028798660398803 -0.00325244127537946" rpy="0 0 0" />
      <mass value="0.0104910911949307" />
      <inertia  ixx="4.757457359033471e-06" ixy="0" ixz="0" iyy="7.755729186462954e-07" iyz="0" izz="4.966511401928294e-06" />
    </inertial>
    <visual>
      <origin xyz="0 0 0" rpy="0 0 0" />
      <geometry>
        <mesh filename="package://centauri/meshes/pinza2.STL" />
      </geometry>
      <material name="centauri_yellow"/>
    </visual>
    <collision>
      <origin xyz="0 0 0" rpy="0 0 0" />
      <geometry>
        <mesh filename="package://centauri/meshes/pinza2.STL" />
      </geometry>
    </collision>
  </link>

  <joint name="joint_pinza2" type="revolute">
    <origin xyz="-0.0399999999999999 0 0" rpy="1.97708169280553E-13 0 1.18785190017512E-15" />
    <parent link="gear2" />
    <child link="pinza2" />
    <axis xyz="0 0 1" />
    <limit lower="-1.5" upper="0" effort="5" velocity="1" />
    <mimic joint="joint_gear2" multiplier="-1" offset="0"/>
    <dynamics friction="1.5" />
  </joint>

<!--//////////////////////////////////////////////////////////-->
  <link name="pivot1">
    <inertial>
      <origin xyz="-0.019999999999913 3.73034936274053E-14 -0.00299999999909059" rpy="0 0 0" />
      <mass value="0.00167027391699942" />
      <inertia  ixx="1.3887110424777991e-08" ixy="0" ixz="0" iyy="3.2498259093576485e-07" iyz="0" izz="3.2884805768432345e-07" />
    </inertial>
    <visual>
      <origin xyz="0 0 0" rpy="0 0 0" />
      <geometry>
        <mesh filename="package://centauri/meshes/pivot1.STL" />
      </geometry>
      <material name="centauri_yellow"/>
    </visual>
    <collision>
      <origin xyz="0 0 0" rpy="0 0 0" />
      <geometry>
        <mesh filename="package://centauri/meshes/pivot1.STL" />
      </geometry>
    </collision>
  </link>

  <joint name="joint_pivot1" type="revolute">
    <origin xyz="-0.00718356702735162 -0.0025224669175542 0.044000380969009" rpy="1.57089248092551 0.383949555179722 -0.0673010584807898" />
    <parent link="link6" />
    <child link="pivot1" />
    <axis xyz="0 0 1" />
    <limit lower="-1.5708" upper="1.5708" effort="5" velocity="1" />
    <mimic joint="joint_gear1" multiplier="1" offset="0"/> 
    <dynamics friction="1.5" />
  </joint>

<!--//////////////////////////////////////////////////////////-->
  <link name="pivot2">
    <inertial>
      <origin xyz="-0.0200000000003783 1.7963408538435E-13 -0.00299999999915881" rpy="0 0 0" />
      <mass value="0.00167027391699937" />
      <inertia  ixx="1.3887110424777991e-08" ixy="0" ixz="0" iyy="3.2498259093576485e-07" iyz="0" izz="3.2884805768432345e-07" />
    </inertial>
    <visual>
      <origin xyz="0 0 0" rpy="0 0 0" />
      <geometry>
        <mesh filename="package://centauri/meshes/pivot2.STL" />
      </geometry>
      <material name="centauri_yellow"/>
    </visual>
    <collision>
      <origin xyz="0 0 0" rpy="0 0 0" />
      <geometry>
        <mesh
          filename="package://centauri/meshes/pivot2.STL" />
      </geometry>
    </collision>
  </link>

  <joint name="joint_pivot2" type="revolute">
    <origin xyz="0.00678474024778378 -0.00346395049278106 0.0439996403025864" rpy="-1.57089245405947 0.400771502354882 3.07429454658117" />
    <parent link="link6" />
    <child link="pivot2" />
    <axis xyz="0 0 1" />
    <limit lower="-1.5708" upper="1.5708" effort="5" velocity="1" />
    <mimic joint="joint_gear2" multiplier="1" offset="0"/>
    <dynamics friction="1.5" />
  </joint>
</robot>
